<!--
Regenerated by loading and saving the original model in MuJoCo 2.3.3 using
/sample/compile oldmodel.xml newmodel.xml
In addition <compiler autolimit="true"> was deleted and explicit limits added, where required.
-->
<mujoco model="hopper">
  <compiler angle="radian"/>
  <option integrator="RK4"/>
  <visual>
    <map znear="0.02"/>
  </visual>
  <default>
    <joint limited="true" armature="1" damping="1"/>
    <geom condim="1" solimp="0.8 0.8 0.01 0.5 2" margin="0.001" material="self"/>
    <general ctrllimited="true" ctrlrange="-0.4 0.4"/>
  </default>
  <custom>
    <numeric name="min_torso_y_angle" size="1" data="-1"/>
    <numeric name="max_torso_y_angle" size="1" data="1"/>
    <numeric name="min_torso_height" size="1" data="0.45"/>
    <numeric name="max_state_vector" size="1" data="100"/>
    <numeric name="ctrl_cost_coeff" size="1" data="0.001"/>
    <numeric name="qpos_random_init_scale" size="1" data="0.005"/>
    <numeric name="qvel_random_init_scale" size="1" data="0.005"/>
    <text name="qpos_random_init_method" data="uniform"/>
    <text name="qvel_random_init_method" data="uniform"/>
  </custom>
  <asset>
    <texture type="2d" name="grid" builtin="checker" mark="edge" rgb1="0.1 0.2 0.3" rgb2="0.2 0.3 0.4" markrgb="0.2 0.3 0.4" width="300" height="300"/>
    <texture type="skybox" name="skybox" builtin="gradient" mark="random" rgb1="0.4 0.6 0.8" rgb2="0 0 0" markrgb="1 1 1" width="800" height="800"/>
    <material name="grid" texture="grid" texuniform="true" reflectance="0.2"/>
    <material name="self" rgba="0.7 0.5 0.3 1"/>
    <material name="self_default" rgba="0.7 0.5 0.3 1"/>
    <material name="self_highlight" rgba="0 0.5 0.3 1"/>
    <material name="effector" rgba="0.7 0.4 0.2 1"/>
    <material name="effector_default" rgba="0.7 0.4 0.2 1"/>
    <material name="effector_highlight" rgba="0 0.5 0.3 1"/>
    <material name="decoration" rgba="0.3 0.5 0.7 1"/>
    <material name="eye" rgba="0 0.2 1 1"/>
    <material name="target" rgba="0.6 0.3 0.3 1"/>
    <material name="target_default" rgba="0.6 0.3 0.3 1"/>
    <material name="target_highlight" rgba="0.6 0.3 0.3 0.4"/>
    <material name="site" rgba="0.5 0.5 0.5 0.3"/>
  </asset>
  <worldbody>
    <geom name="floor" size="20 20 0.125" type="plane" condim="3" material="grid"/>
    <light pos="0 0 1.3" dir="-0.5547 0 -0.83205" directional="true" cutoff="100" exponent="1" diffuse="1 1 1" specular="0.1 0.1 0.1"/>
    <body name="torso" pos="0 0 1.25">
      <joint name="rootx" pos="0 0 -1.25" axis="1 0 0" limited="false" type="slide" armature="0" damping="0"/>
      <joint name="rootz" pos="0 0 -1.25" axis="0 0 1" limited="false" type="slide" ref="1.25" armature="0" damping="0"/>
      <joint name="rooty" pos="0 0 0" axis="0 1 0" limited="false" armature="0" damping="0"/>
      <geom name="torso_geom" size="0.05 0.2" type="capsule" friction="0.9 0.005 0.0001"/>
      <camera name="tilted" pos="2.7 3 -0.25" quat="0.660169 -0.660169 0.253331 -0.253331" mode="trackcom"/>
      <camera name="track" pos="0 3 -0.25" quat="0.707107 -0.707107 0 0" mode="trackcom"/>
      <body name="thigh" pos="0 0 -0.2">
        <joint name="thigh_joint" pos="0 0 0" axis="0 -1 0" range="-2.61799 0" limited="true"/>
        <geom name="thigh_geom" size="0.05 0.225" pos="0 0 -0.225" type="capsule" friction="0.9 0.005 0.0001"/>
        <body name="foot" pos="0.065 0 -0.45">
          <joint name="foot_joint" pos="-0.065 0 0" axis="0 -1 0" range="-0.785398 0.785398" limited="true"/>
          <geom name="foot_geom" size="0.06 0.195" quat="0.707107 0 -0.707107 0" type="capsule" friction="2 0.005 0.0001"/>
        </body>
      </body>
    </body>
  </worldbody>
  <actuator>
    <general joint="thigh_joint" ctrlrange="-1 1" gear="200 0 0 0 0 0" ctrllimited="true"/>
    <general joint="foot_joint" ctrlrange="-1 1" gear="200 0 0 0 0 0" ctrllimited="true"/>
  </actuator>
</mujoco> 
